<mujoco model="ur5e_contact_nomesh_scene">
  <compiler angle="radian" autolimits="true"/>
  <option integrator="implicitfast" gravity="0 0 -9.81"/>

  <default>
    <default class="ur5e">
      <joint axis="0 1 0" range="-6.28319 6.28319" armature="0.1"/>
      <general gaintype="fixed" biastype="affine" ctrlrange="-6.2831 6.2831" gainprm="5000" biasprm="0 -5000 -1000" forcerange="-150 150"/>
      <default class="size3">
        <default class="size3_limited">
          <joint range="-3.1415 3.1415"/>
          <general ctrlrange="-3.1415 3.1415"/>
        </default>
      </default>
      <default class="size1">
        <general gainprm="1000" biasprm="0 -1000 -200" forcerange="-28 28"/>
      </default>
      <default class="collision">
        <geom group="1" rgba="0.65 0.65 0.72 1"/>
        <default class="eef_collision">
          <geom type="cylinder"/>
        </default>
      </default>
      <site size="0.001" rgba="1 0 0 1" group="4"/>
    </default>
  </default>

  <worldbody>
    <light name="spotlight" mode="targetbodycom" target="wrist_2_link" pos="0 -1 2"/>

    <geom name="contact_table" type="box" pos="0.45 -0.25 0.20" size="0.18 0.18 0.20"
          rgba="0.8 0.8 0.9 1" friction="0.5 0.005 0.0001" contype="1" conaffinity="1"/>
    <geom name="floor" type="plane" size="2 2 0.1" pos="0 0 0"
          rgba="0.9 0.9 0.9 1" contype="1" conaffinity="1"/>

    <body name="base" pos="0 0 0" childclass="ur5e">
      <inertial mass="4.0" pos="0 0 0" diaginertia="0.00443333156 0.00443333156 0.0072"/>
      <geom class="collision" type="cylinder" pos="0 0 0.08" size="0.08 0.08"/>

      <body name="shoulder_link" pos="0 0 0.163">
        <inertial mass="3.7" pos="0 0 0" diaginertia="0.0102675 0.0102675 0.00666"/>
        <joint name="shoulder_pan_joint" class="size3" axis="0 0 1"/>
        <geom class="collision" size="0.06 0.06" pos="0 0 -0.04"/>

        <body name="upper_arm_link" pos="0 0.138 0" quat="1 0 1 0">
          <inertial mass="8.393" pos="0 0 0.2125" diaginertia="0.133886 0.133886 0.0151074"/>
          <joint name="shoulder_lift_joint" class="size3"/>
          <geom class="collision" pos="0 -0.04 0" quat="1 1 0 0" size="0.06 0.06"/>
          <geom class="collision" type="capsule" size="0.05 0.2" pos="0 0 0.2"/>

          <body name="forearm_link" pos="0 -0.131 0.425">
            <inertial mass="2.275" pos="0 0 0.196" diaginertia="0.0311796 0.0311796 0.004095"/>
            <joint name="elbow_joint" class="size3_limited"/>
            <geom class="collision" pos="0 0.08 0" quat="1 1 0 0" size="0.055 0.06"/>
            <geom class="collision" type="capsule" size="0.038 0.19" pos="0 0 0.2"/>

            <body name="wrist_1_link" pos="0 0 0.392" quat="1 0 1 0">
              <inertial mass="1.219" pos="0 0.127 0" diaginertia="0.0025599 0.0025599 0.0021942"/>
              <joint name="wrist_1_joint" class="size1"/>
              <geom class="collision" pos="0 0.05 0" quat="1 1 0 0" size="0.04 0.07"/>

              <body name="wrist_2_link" pos="0 0.127 0">
                <inertial mass="1.219" pos="0 0 0.1" diaginertia="0.0025599 0.0025599 0.0021942"/>
                <joint name="wrist_2_joint" axis="0 0 1" class="size1"/>
                <geom class="collision" type="cylinder" size="0.04 0.06" pos="0 0 0.04"/>
                <geom class="collision" pos="0 0.02 0.1" quat="1 1 0 0" size="0.04 0.04"/>

                <body name="wrist_3_link" pos="0 0 0.1">
                  <inertial mass="0.1889" pos="0 0.0771683 0" quat="1 0 0 1" diaginertia="0.000132134 9.90863e-05 9.90863e-05"/>
                  <joint name="wrist_3_joint" class="size1"/>
                  <geom class="eef_collision" pos="0 0.08 0" quat="1 1 0 0" size="0.04 0.02"/>
                  <site name="attachment_site" pos="0 0.1 0" quat="-1 1 0 0"/>

                  <body name="flange" pos="0 0.090 0" quat="0.707107 -0.707107 0 0">
                    <body name="tool0" pos="0 0 0.221">
                      <site name="ee_site" type="cylinder" size="0.0375 0.0001" pos="0 0 0" euler="0 0 0" rgba="1 0 0 1"/>
                      <geom name="ee_contact_disk" type="cylinder" size="0.03 0.0025"
                            pos="0 0 0" quat="1 0 0 0"
                            rgba="0.2 0.7 0.2 0.5" contype="1" conaffinity="1"
                            friction="0.8 0.005 0.0001" mass="0.05"
                            solref="0.01 1.0" solimp="0.9 0.95 0.001 0.5 2"/>
                    </body>
                  </body>
                </body>
              </body>
            </body>
          </body>
        </body>
      </body>
    </body>
  </worldbody>

  <actuator>
    <general class="size3" name="shoulder_pan" joint="shoulder_pan_joint"/>
    <general class="size3" name="shoulder_lift" joint="shoulder_lift_joint"/>
    <general class="size3_limited" name="elbow" joint="elbow_joint"/>
    <general class="size1" name="wrist_1" joint="wrist_1_joint"/>
    <general class="size1" name="wrist_2" joint="wrist_2_joint"/>
    <general class="size1" name="wrist_3" joint="wrist_3_joint"/>
  </actuator>

  <sensor>
    <force name="ee_force_sensor" site="ee_site"/>
    <torque name="ee_torque_sensor" site="ee_site"/>
  </sensor>
</mujoco>
