<mujoco model="ur5e">
  <compiler angle="radian" meshdir="assets" autolimits="true"/>
  <!-- <include file="../AFPhead/mjcf/AFPhead.xml"/> -->
  <option integrator="implicitfast" gravity="0 0 -9.81"/>

  <default>
    <default class="ur5e">
      <material specular="0.5" shininess="0.25"/>
      <joint axis="0 1 0" range="-6.28319 6.28319" armature="0.1"/>
      <general gaintype="fixed" biastype="affine" ctrlrange="-6.2831 6.2831" gainprm="2000" biasprm="0 -2000 -200" forcerange="-150 150"/>
      <default class="size3">
        <default class="size3_limited">
          <joint range="-3.1415 3.1415"/>
          <general ctrlrange="-3.1415 3.1415"/>
        </default>
      </default>
      <default class="size1">
        <general gainprm="1000" biasprm="0 -1000 -200" forcerange="-28 28"/>
      </default>
      <default class="visual">
        <geom type="mesh" contype="0" conaffinity="0" group="2"/>
      </default>
      <default class="collision">
        <geom type="capsule" group="3"/>
        <default class="eef_collision">
          <geom type="cylinder"/>
        </default>
      </default>
      <site size="0.001" rgba="0.5 0.5 0.5 0.3" group="4"/>
    </default>
    <!-- robotiq_gripper -->
    <default class="2f85">
      <mesh scale="0.001 0.001 0.001"/>
      <!-- <general ctrllimited="true" forcelimited="true" biastype="none"/> -->
      <joint axis="1 0 0" limited="false"/>
      <default class="robotiq_85_outter_knuckle_link">
        <joint limited="true" range="0 0.834" solimplimit="0.95 0.99 0.001" solreflimit="0.005 1" armature="0.005" damping="0.1" />
      </default>
      <default class="robotiq_85_finger_tip_link">
        <joint limited="true" armature="0.001" range="-0.872664 0.872664" pos="0 -0.018 0.0065" solimplimit="0.95 0.99 0.001" solreflimit="0.005 1"/>
      </default>
      <default class="robotiq_85_inner_knuckle_link">
        <joint limited="true" armature="0.001" range="-0.29670597283 0.8" stiffness="0.05" springref="2.62" damping="0.00125"/>
      </default>
      <default class="robotiq_85_finger_link">
        <joint limited="true" armature="0.001" range="-1.57 0" solimplimit="0.95 0.99 0.001" solreflimit="0.005 1"/>
      </default>
      <default class="visual_2f85">
        <geom type="mesh" contype="0" conaffinity="0" group="2"/>
      </default>
      <default class="collision_2f85">
        <geom type="mesh" group="3"/>
        <default class="robotiq_85_finger_pad_box1">
          <geom mass="0.0" type="box" pos="0 -0.0026 0.028125" size="0.011 0.004 0.009375" friction="0.7" solimp="0.95 0.99 0.001" solref="0.004 1" priority="1" rgba="0.55 0.55 0.55 1"/>
          <!-- mass="0.1" -->
        </default>
        <default class="robotiq_85_finger_pad_box2">
          <geom mass="0.0" type="box" pos="0 -0.0026 0.009375" size="0.011 0.004 0.009375" friction="0.6" solimp="0.95 0.99 0.001" solref="0.004 1" priority="1" rgba="0.45 0.45 0.45 1"/>
          <!-- mass="0.1" -->
        </default>
      </default>
    </default>


  </default>

  <asset>
    <material class="ur5e" name="black" rgba="0.033 0.033 0.033 1"/>
    <material class="ur5e" name="jointgray" rgba="0.278 0.278 0.278 1"/>
    <material class="ur5e" name="linkgray" rgba="0.82 0.82 0.82 1"/>
    <material class="ur5e" name="urblue" rgba="0.49 0.678 0.8 1"/>


    <mesh name="afp_base_link" file="../../AFPhead/meshes/base_link.STL"/>
    <mesh name="afp_shoujuan_link" file="../../AFPhead/meshes/shoujuan_link.STL"/>
    <mesh name="afp_fangjuan_link" file="../../AFPhead/meshes/fangjuan_link.STL"/>
    <mesh name="afp_roll_link" file="../../AFPhead/meshes/roll_link.STL"/>
    <mesh name="afp_chongsong_link" file="../../AFPhead/meshes/chongsong_link.STL"/>

    <mesh file="base_0.obj"/>
    <mesh file="base_1.obj"/>
    <mesh file="shoulder_0.obj"/>
    <mesh file="shoulder_1.obj"/>
    <mesh file="shoulder_2.obj"/>
    <mesh file="upperarm_0.obj"/>
    <mesh file="upperarm_1.obj"/>
    <mesh file="upperarm_2.obj"/>
    <mesh file="upperarm_3.obj"/>
    <mesh file="forearm_0.obj"/>
    <mesh file="forearm_1.obj"/>
    <mesh file="forearm_2.obj"/>
    <mesh file="forearm_3.obj"/>
    <mesh file="wrist1_0.obj"/>
    <mesh file="wrist1_1.obj"/>
    <mesh file="wrist1_2.obj"/>
    <mesh file="wrist2_0.obj"/>
    <mesh file="wrist2_1.obj"/>
    <mesh file="wrist2_2.obj"/>
    <mesh file="wrist3.obj"/>
  </asset>

  <worldbody>
    <light name="spotlight" mode="targetbodycom" target="wrist_2_link" pos="0 -1 2"/>
    <body name="base" pos = "0.0 0.0 0" quat="0 0 0 1" childclass="ur5e">
      <inertial mass="4.0" pos="0 0 0" diaginertia="0.00443333156 0.00443333156 0.0072"/>
      <geom mesh="base_0" material="black" class="visual"/>
      <geom mesh="base_1" material="jointgray" class="visual"/>
      <body name="shoulder_link" pos="0 0 0.163">
        <inertial mass="3.7" pos="0 0 0" diaginertia="0.0102675 0.0102675 0.00666"/>
        <joint name="shoulder_pan_joint" class="size3" axis="0 0 1"/>
        <geom mesh="shoulder_0" material="urblue" class="visual"/>
        <geom mesh="shoulder_1" material="black" class="visual"/>
        <geom mesh="shoulder_2" material="jointgray" class="visual"/>
        <geom class="collision" size="0.06 0.06" pos="0 0 -0.04"/>
        <body name="upper_arm_link" pos="0 0.138 0" quat="1 0 1 0">
          <inertial mass="8.393" pos="0 0 0.2125" diaginertia="0.133886 0.133886 0.0151074"/>
          <joint name="shoulder_lift_joint" class="size3"/>
          <geom mesh="upperarm_0" material="linkgray" class="visual"/>
          <geom mesh="upperarm_1" material="black" class="visual"/>
          <geom mesh="upperarm_2" material="jointgray" class="visual"/>
          <geom mesh="upperarm_3" material="urblue" class="visual"/>
          <geom class="collision" pos="0 -0.04 0" quat="1 1 0 0" size="0.06 0.06"/>
          <geom class="collision" size="0.05 0.2" pos="0 0 0.2"/>
          <body name="forearm_link" pos="0 -0.131 0.425">
            <inertial mass="2.275" pos="0 0 0.196" diaginertia="0.0311796 0.0311796 0.004095"/>
            <joint name="elbow_joint" class="size3_limited"/>
            <geom mesh="forearm_0" material="urblue" class="visual"/>
            <geom mesh="forearm_1" material="linkgray" class="visual"/>
            <geom mesh="forearm_2" material="black" class="visual"/>
            <geom mesh="forearm_3" material="jointgray" class="visual"/>
            <geom class="collision" pos="0 0.08 0" quat="1 1 0 0" size="0.055 0.06"/>
            <geom class="collision" size="0.038 0.19" pos="0 0 0.2"/>
            <body name="wrist_1_link" pos="0 0 0.392" quat="1 0 1 0">
              <inertial mass="1.219" pos="0 0.127 0" diaginertia="0.0025599 0.0025599 0.0021942"/>
              <joint name="wrist_1_joint" class="size1"/>
              <geom mesh="wrist1_0" material="black" class="visual"/>
              <geom mesh="wrist1_1" material="urblue" class="visual"/>
              <geom mesh="wrist1_2" material="jointgray" class="visual"/>
              <geom class="collision" pos="0 0.05 0" quat="1 1 0 0" size="0.04 0.07"/>
              <body name="wrist_2_link" pos="0 0.127 0">
                <inertial mass="1.219" pos="0 0 0.1" diaginertia="0.0025599 0.0025599 0.0021942"/>
                <joint name="wrist_2_joint" axis="0 0 1" class="size1"/>
                <geom mesh="wrist2_0" material="black" class="visual"/>
                <geom mesh="wrist2_1" material="urblue" class="visual"/>
                <geom mesh="wrist2_2" material="jointgray" class="visual"/>
                <geom class="collision" size="0.04 0.06" pos="0 0 0.04"/>
                <geom class="collision" pos="0 0.02 0.1" quat="1 1 0 0" size="0.04 0.04"/>
                <body name="wrist_3_link" pos="0 0 0.1">
                  <inertial mass="0.1889" pos="0 0.0771683 0" quat="1 0 0 1" diaginertia="0.000132134 9.90863e-05 9.90863e-05"/>
                  <joint name="wrist_3_joint" class="size1"/>
                  <geom material="linkgray" mesh="wrist3" class="visual"/>
                  <geom class="eef_collision" pos="0 0.08 0" quat="1 1 0 0" size="0.04 0.02"/>
                  <site name="attachment_site" pos="0 0.1 0" quat="-1 1 0 0"/>
                  <body name="flange" pos="0 0.090 0" quat="0.707107 -0.707107 0 0">
                    <!-- <inertial pos="0 0.090 0" quat="0.707107 -0.707107 0 0" mass="0" diaginertia="0 0 0" /> -->
                    <!-- FT-Sensor -->
                    <!-- <site name="ee_site" type="cylinder" size="0.0375 0.0001" pos="0 0.0 0.0" euler="0 0 0" rgba="1 0 0 1" /> -->
                    <!-- <body pos="0 0.09 0" quat="0.707107 -0.707107 0 0"> -->
                    <include file="../AFPhead/mjcf/AFPhead_attached.xml"/>
                    <!-- </body> -->
                    <!-- This camera points out from the eef. -->
                    <!--<camera name="gripper_camera" euler="0 3.14159265 0" fovy="63.5" /> -->
                    <!-- robotiq_based_joint -->
                  </body>
                </body>
              </body>
            </body>
          </body>
        </body>
      </body>
    </body>
  </worldbody>

  <actuator>
    <general class="size3" name="shoulder_pan" joint="shoulder_pan_joint"/>
    <general class="size3" name="shoulder_lift" joint="shoulder_lift_joint"/>
    <general class="size3_limited" name="elbow" joint="elbow_joint"/>
    <general class="size3" name="wrist_1" joint="wrist_1_joint"/>
    <general class="size3" name="wrist_2" joint="wrist_2_joint"/>
    <general class="size3" name="wrist_3" joint="wrist_3_joint"/>
    <!-- <motor name="afp_shoujuan" joint="afp_shoujuan_joint" gear="1" ctrllimited="true" ctrlrange="-10 10"/>
    <motor name="afp_fangjuan" joint="afp_fangjuan_joint" gear="1" ctrllimited="true" ctrlrange="-10 10"/>
    <motor name="afp_roll" joint="afp_roll_joint" gear="1" ctrllimited="true" ctrlrange="-5 5"/>
    <motor name="afp_chongsong" joint="afp_chongsong_joint" gear="1" ctrllimited="true" ctrlrange="-5 5"/> -->
  </actuator>


  <sensor>
    <force name="ee_force_sensor" site="ee_site" />
    <torque name="ee_torque_sensor" site="ee_site" />
  </sensor>


  <!-- <keyframe>
    <key name="home" qpos="-1.5708 -1.5708 1.5708 -1.5708 -1.5708 0 0 0 0 0" ctrl="-1.5708 -1.5708 1.5708 -1.5708 -1.5708 0 0 0 0 0"/>
  </keyframe> -->

</mujoco>
